
// A Promise is a proxy for a value not necessarily known when the promise is created
// It allows you to associate handlers with an asynchronous action's eventual success value or failure reason

//  Promise is in one of these states:
// 1. pending: initial state, neither fulfilled nor rejected.
// 2. fulfilled: meaning that the operation was completed successfully.
// 3. rejected: meaning that the operation failed.


// A Promise callback function is slightly longer to define but the real benefit comes when chaining callbacks

// Example of a vanilla fake request callback function
const fakeRequestCallback = (url, success, failure) => {
    const delay = Math.floor(Math.random() * 4500) + 500;
    setTimeout(() => {
        if (delay > 4000) {
            failure('Connection Timeout :(')
        } else {
            success(`Here is your fake data from ${url}`)
        }
    }, delay)
}

// // Example of a promise fake request callback function
const fakeRequestPromise = (url) => {
    return new Promise((resolve, reject) => {
        const delay = Math.floor(Math.random() * (4500)) + 500;
        setTimeout(() => {
            if (delay > 4000) {
                reject('Connection Timeout :(')
            } else {
                resolve(`Here is your fake data from ${url}`)
            }
        }, delay)
    })
}

// Example of chained callbacks

// If you have a lot of chained tasks you can end up with multi-level nested functions which are ugly and difficult to read
// This is known as 'callback hell' and can cause major problems if you need to edit this code
fakeRequestCallback('books.com/page1',
    function (response) {
        console.log("IT WORKED!!!!")
        console.log(response)
        fakeRequestCallback('books.com/page2',
            function (response) {
                console.log("IT WORKED AGAIN!!!!")
                console.log(response)
                fakeRequestCallback('books.com/page3',
                    function (response) {
                        console.log("IT WORKED AGAIN (3rd req)!!!!")
                        console.log(response)
                    },
                    function (err) {
                        console.log("ERROR (3rd req)!!!", err)
                    })
            },
            function (err) {
                console.log("ERROR (2nd req)!!!", err)
            })
    }, function (err) {
        console.log("ERROR!!!", err)
    })


// Example using promises with then/catch

// The then() method returns a Promise. It takes up to two arguments: callback functions for the success and failure cases of the Promise.
// The catch() method returns a Promise and deals with rejected cases only

// RETURN A PROMISE FROM .THEN() CALLBACK SO WE CAN CHAIN!
fakeRequestPromise('yelp.com/api/coffee/page1')
    .then((data) => {
        console.log("IT WORKED!!!!!! (page1)")
        console.log(data)
        return fakeRequestPromise('yelp.com/api/coffee/page2')
    })
    .then((data) => {
        console.log("IT WORKED!!!!!! (page2)")
        console.log(data)
        return fakeRequestPromise('yelp.com/api/coffee/page3')
    })
    .then((data) => {
        console.log("IT WORKED!!!!!! (page3)")
        console.log(data)
    })
    .catch((err) => {
        console.log("OH NO, A REQUEST FAILED!!!")
        console.log(err)
    })


// If you don't return a promise, you have to nest them to get the same effect
// DO NOT DO THIS!
fakeRequestPromise('yelp.com/api/coffee/page1')
    .then(() => {
        console.log("IT WORKED!!!!!! (page1)")
        fakeRequestPromise('yelp.com/api/coffee/page2')
            .then(() => {
                console.log("IT WORKED!!!!!! (page2)")
                fakeRequestPromise('yelp.com/api/coffee/page3')
                    .then(() => {
                        console.log("IT WORKED!!!!!! (page3)")
                    })
                    .catch(() => {
                        console.log("OH NO, ERROR!!! (page3)")
                    })
            })
            .catch(() => {
                console.log("OH NO, ERROR!!! (page2)")
            })
    })
    .catch(() => {
        console.log("OH NO, ERROR!!! (page1)")
    })